<mujoco model="mycobot_280">
  <compiler angle="radian" meshdir="../meshes_mujoco"/>

  <option integrator="implicitfast"/>

  <!-- ================= DEFAULTS ================= -->
  <default>

    <!-- Visual geometry -->
    <default class="visual">
      <geom type="mesh"
            rgba="0.7 0.7 0.7 1"
            contype="0"
            conaffinity="0"
            group="2"/>
    </default>

    <!-- Collision geometry (unused here) -->
    <default class="collision">
      <geom type="capsule"
            group="3"
            contype="1"
            conaffinity="1"/>
    </default>

    <!-- Joint defaults -->
    <joint damping="1" armature="0.05" axis="0 0 1"/>

  </default>

  <!-- ================= ASSETS ================= -->
  <asset>
    <!-- Visual meshes (OBJ) -->
    <mesh name="joint1_vis" file="../meshes_mujoco/joint1_jet.obj"/>
    <mesh name="joint2_vis" file="../meshes_mujoco/joint2.obj"/>
    <mesh name="joint3_vis" file="../meshes_mujoco/joint3.obj"/>
    <mesh name="joint4_vis" file="../meshes_mujoco/joint4.obj"/>
    <mesh name="joint5_vis" file="../meshes_mujoco/joint5.obj"/>
    <mesh name="joint6_vis" file="../meshes_mujoco/joint6.obj"/>
    <mesh name="joint7_vis" file="../meshes_mujoco/joint7.obj"/>
  </asset>

  <!-- ================= WORLD ================= -->
  <worldbody>

    <!-- Base -->
    <body name="base" pos="0 0 0">
      <geom mesh="joint1_vis" class="visual"/>

      <!-- Joint 2 -->
      <body name="joint2" pos="0 0 0.15756">
        <joint name="joint2"/>
        <geom mesh="joint2_vis"
              pos="0 0 -0.06096"
              quat="0.707105 0 0 -0.707108"
              class="visual"/>

        <!-- Joint 3 -->
        <body name="joint3" pos="0 0 -0.001"
              quat="0.499998 0.500002 0.5 -0.5">
          <joint name="joint3"/>
          <geom mesh="joint3_vis"
                pos="0 0 0.03256"
                quat="0.707105 0 -0.707108 0"
                class="visual"/>

          <!-- Joint 4 -->
          <body name="joint4" pos="-0.1104 0 0">
            <joint name="joint4"/>
            <geom mesh="joint4_vis"
                  pos="0 0 0.03056"
                  quat="0.707105 0 -0.707108 0"
                  class="visual"/>

            <!-- Joint 5 -->
            <body name="joint5" pos="-0.096 0 0.06462"
                  quat="0.707105 0 0 -0.707108">
              <joint name="joint5"/>
              <geom mesh="joint5_vis"
                    pos="0 0 -0.03356"
                    quat="0.707105 -0.707108 0 0"
                    class="visual"/>

              <!-- Joint 6 -->
              <body name="joint6" pos="0 -0.07318 0"
                    quat="0.499998 0.5 -0.5 0.500002">
                <joint name="joint6"/>
                <geom mesh="joint6_vis"
                      pos="0 0 -0.038"
                      class="visual"/>

                <!-- Flange / Joint 7 -->
                <body name="joint6_flange" pos="0 0.0456 0"
                      quat="0.707105 -0.707108 0 0">
                  <joint name="joint7"/>
                  <geom mesh="joint7_vis"
                        pos="0 0 -0.012"
                        class="visual"/>
                </body>

              </body>
            </body>
          </body>
        </body>
      </body>
    </body>

  </worldbody>

  <!-- ================= KEYFRAME ================= -->
  <keyframe>
    <key name="home" qpos="0 0 0 0 0 0"/>
  </keyframe>

</mujoco>
