#usda 1.0
(
    customLayerData = {
        string creator = "MuJoCo USD Converter v0.1.0a3"
    }
    defaultPrim = "tn__xarm7scene_lA"
    kilogramsPerUnit = 1
    metersPerUnit = 1
    upAxis = "Z"
)

def Xform "tn__xarm7scene_lA" (
    displayName = "xarm7 scene"
)
{
    def Scope "Physics"
    {
        def Material "PhysicsMaterial" (
            prepend apiSchemas = ["PhysicsMaterialAPI", "MjcMaterialAPI"]
        )
        {
            float physics:dynamicFriction = 1
        }

        def Material "PhysicsMaterial_1" (
            prepend apiSchemas = ["PhysicsMaterialAPI", "MjcMaterialAPI"]
        )
        {
            float physics:dynamicFriction = 0.7
        }

        def Material "PhysicsMaterial_2" (
            prepend apiSchemas = ["PhysicsMaterialAPI", "MjcMaterialAPI"]
        )
        {
            float physics:dynamicFriction = 0.6
        }

        def MjcActuator "act1"
        {
            uniform double[] mjc:biasPrm = [0, -1500, -150, 0, 0, 0, 0, 0, 0, 0]
            uniform token mjc:biasType = "affine"
            uniform double mjc:ctrlRange:max = 6.28319
            uniform double mjc:ctrlRange:min = -6.28319
            uniform double mjc:forceRange:max = 50
            uniform double mjc:forceRange:min = -50
            uniform double[] mjc:gainPrm = [1500, 0, 0, 0, 0, 0, 0, 0, 0, 0]
            rel mjc:target = </tn__xarm7scene_lA/Geometry/link_base/link1/joint1>
        }

        def MjcActuator "act2"
        {
            uniform double[] mjc:biasPrm = [0, -1500, -150, 0, 0, 0, 0, 0, 0, 0]
            uniform token mjc:biasType = "affine"
            uniform double mjc:ctrlRange:max = 2.0944
            uniform double mjc:ctrlRange:min = -2.059
            uniform double mjc:forceRange:max = 50
            uniform double mjc:forceRange:min = -50
            uniform double[] mjc:gainPrm = [1500, 0, 0, 0, 0, 0, 0, 0, 0, 0]
            rel mjc:target = </tn__xarm7scene_lA/Geometry/link_base/link1/link2/joint2>
        }

        def MjcActuator "act3"
        {
            uniform double[] mjc:biasPrm = [0, -1000, -100, 0, 0, 0, 0, 0, 0, 0]
            uniform token mjc:biasType = "affine"
            uniform double mjc:ctrlRange:max = 6.28319
            uniform double mjc:ctrlRange:min = -6.28319
            uniform double mjc:forceRange:max = 30
            uniform double mjc:forceRange:min = -30
            uniform double[] mjc:gainPrm = [1000, 0, 0, 0, 0, 0, 0, 0, 0, 0]
            rel mjc:target = </tn__xarm7scene_lA/Geometry/link_base/link1/link2/link3/joint3>
        }

        def MjcActuator "act4"
        {
            uniform double[] mjc:biasPrm = [0, -1000, -100, 0, 0, 0, 0, 0, 0, 0]
            uniform token mjc:biasType = "affine"
            uniform double mjc:ctrlRange:max = 3.927
            uniform double mjc:ctrlRange:min = -0.19198
            uniform double mjc:forceRange:max = 30
            uniform double mjc:forceRange:min = -30
            uniform double[] mjc:gainPrm = [1000, 0, 0, 0, 0, 0, 0, 0, 0, 0]
            rel mjc:target = </tn__xarm7scene_lA/Geometry/link_base/link1/link2/link3/link4/joint4>
        }

        def MjcActuator "act5"
        {
            uniform double[] mjc:biasPrm = [0, -1000, -100, 0, 0, 0, 0, 0, 0, 0]
            uniform token mjc:biasType = "affine"
            uniform double mjc:ctrlRange:max = 6.28319
            uniform double mjc:ctrlRange:min = -6.28319
            uniform double mjc:forceRange:max = 30
            uniform double mjc:forceRange:min = -30
            uniform double[] mjc:gainPrm = [1000, 0, 0, 0, 0, 0, 0, 0, 0, 0]
            rel mjc:target = </tn__xarm7scene_lA/Geometry/link_base/link1/link2/link3/link4/link5/joint5>
        }

        def MjcActuator "act6"
        {
            uniform double[] mjc:biasPrm = [0, -800, -80, 0, 0, 0, 0, 0, 0, 0]
            uniform token mjc:biasType = "affine"
            uniform double mjc:ctrlRange:max = 3.14159
            uniform double mjc:ctrlRange:min = -1.69297
            uniform double mjc:forceRange:max = 20
            uniform double mjc:forceRange:min = -20
            uniform double[] mjc:gainPrm = [800, 0, 0, 0, 0, 0, 0, 0, 0, 0]
            rel mjc:target = </tn__xarm7scene_lA/Geometry/link_base/link1/link2/link3/link4/link5/link6/joint6>
        }

        def MjcActuator "act7"
        {
            uniform double[] mjc:biasPrm = [0, -800, -80, 0, 0, 0, 0, 0, 0, 0]
            uniform token mjc:biasType = "affine"
            uniform double mjc:ctrlRange:max = 6.28319
            uniform double mjc:ctrlRange:min = -6.28319
            uniform double mjc:forceRange:max = 20
            uniform double mjc:forceRange:min = -20
            uniform double[] mjc:gainPrm = [800, 0, 0, 0, 0, 0, 0, 0, 0, 0]
            rel mjc:target = </tn__xarm7scene_lA/Geometry/link_base/link1/link2/link3/link4/link5/link6/link7/joint7>
        }

        def MjcActuator "gripper"
        {
        }
    }

    def "Geometry"
    {
        over "floor" (
            prepend apiSchemas = ["PhysicsCollisionAPI", "MjcCollisionAPI", "MaterialBindingAPI"]
        )
        {
            rel material:binding:physics = </tn__xarm7scene_lA/Physics/PhysicsMaterial>
        }

        over "Cylinder" (
            prepend apiSchemas = ["PhysicsCollisionAPI", "MjcCollisionAPI", "MaterialBindingAPI"]
        )
        {
            rel material:binding:physics = </tn__xarm7scene_lA/Physics/PhysicsMaterial>
        }

        def "link_base" (
            prepend apiSchemas = ["PhysicsRigidBodyAPI", "PhysicsMassAPI", "PhysicsArticulationRootAPI"]
        )
        {
            point3f physics:centerOfMass = (-0.021131, -0.0016302, 0.056488)
            float3 physics:diagonalInertia = (0.00382023, 0.00335282, 0.00167725)
            float physics:mass = 0.88556
            quatf physics:principalAxes = (0.696843, 0.20176, 0.10388, 0.680376)

            over "link_base" (
                prepend apiSchemas = ["PhysicsCollisionAPI", "MjcCollisionAPI", "PhysicsMeshCollisionAPI", "MaterialBindingAPI"]
            )
            {
                rel material:binding:physics = </tn__xarm7scene_lA/Physics/PhysicsMaterial>
                uniform token physics:approximation = "convexHull"
            }

            def PhysicsFixedJoint "PhysicsFixedJoint"
            {
                rel physics:body0 = </tn__xarm7scene_lA>
                rel physics:body1 = </tn__xarm7scene_lA/Geometry/link_base>
                point3f physics:localPos0 = (0, 0, 0.12)
                point3f physics:localPos1 = (0, 0, 0)
                quatf physics:localRot0 = (1, 0, 0, 0)
                quatf physics:localRot1 = (1, 0, 0, 0)
            }

            def "link1" (
                prepend apiSchemas = ["PhysicsRigidBodyAPI", "PhysicsMassAPI"]
            )
            {
                point3f physics:centerOfMass = (-0.0002, 0.02905, -0.01233)
                float3 physics:diagonalInertia = (0.00569127, 0.00533384, 0.00293865)
                float physics:mass = 2.382
                quatf physics:principalAxes = (0.978953, -0.202769, -0.00441617, -0.0227264)

                over "link1" (
                    prepend apiSchemas = ["PhysicsCollisionAPI", "MjcCollisionAPI", "PhysicsMeshCollisionAPI", "MaterialBindingAPI"]
                )
                {
                    rel material:binding:physics = </tn__xarm7scene_lA/Physics/PhysicsMaterial>
                    uniform token physics:approximation = "convexHull"
                }

                def PhysicsRevoluteJoint "joint1" (
                    prepend apiSchemas = ["MjcJointAPI"]
                )
                {
                    uniform double mjc:armature = 0.1
                    uniform double mjc:damping = 10
                    uniform double mjc:frictionloss = 1
                    uniform token physics:axis = "Z"
                    rel physics:body0 = </tn__xarm7scene_lA/Geometry/link_base>
                    rel physics:body1 = </tn__xarm7scene_lA/Geometry/link_base/link1>
                    point3f physics:localPos0 = (0, 0, 0.267)
                    point3f physics:localPos1 = (0, 0, 0)
                    quatf physics:localRot0 = (1, 0, 0, 0)
                    quatf physics:localRot1 = (1, 0, 0, 0)
                    float physics:lowerLimit = -360.00027
                    float physics:upperLimit = 360.00027
                }

                def "link2" (
                    prepend apiSchemas = ["PhysicsRigidBodyAPI", "PhysicsMassAPI"]
                )
                {
                    point3f physics:centerOfMass = (0.00022, -0.12856, 0.01735)
                    float3 physics:diagonalInertia = (0.00959898, 0.00937717, 0.00201315)
                    float physics:mass = 1.869
                    quatf physics:principalAxes = (0.50198, 0.86483, -0.00778841, 0.00483285)

                    over "link2" (
                        prepend apiSchemas = ["PhysicsCollisionAPI", "MjcCollisionAPI", "PhysicsMeshCollisionAPI", "MaterialBindingAPI"]
                    )
                    {
                        rel material:binding:physics = </tn__xarm7scene_lA/Physics/PhysicsMaterial>
                        uniform token physics:approximation = "convexHull"
                    }

                    def PhysicsRevoluteJoint "joint2" (
                        prepend apiSchemas = ["MjcJointAPI"]
                    )
                    {
                        uniform double mjc:armature = 0.1
                        uniform double mjc:damping = 10
                        uniform double mjc:frictionloss = 1
                        uniform token physics:axis = "Z"
                        rel physics:body0 = </tn__xarm7scene_lA/Geometry/link_base/link1>
                        rel physics:body1 = </tn__xarm7scene_lA/Geometry/link_base/link1/link2>
                        point3f physics:localPos0 = (0, 0, 0)
                        point3f physics:localPos1 = (0, 0, 0)
                        quatf physics:localRot0 = (-0.70710677, 0.70710677, 0, 0)
                        quatf physics:localRot1 = (1, 0, 0, 0)
                        float physics:lowerLimit = -117.97201
                        float physics:upperLimit = 120.00028
                    }

                    def "link3" (
                        prepend apiSchemas = ["PhysicsRigidBodyAPI", "PhysicsMassAPI"]
                    )
                    {
                        point3f physics:centerOfMass = (0.0466, -0.02463, -0.00768)
                        float3 physics:diagonalInertia = (0.00351721, 0.00294089, 0.00195868)
                        float physics:mass = 1.6383
                        quatf physics:principalAxes = (0.913819, 0.289775, 0.281481, -0.0416455)

                        over "link3" (
                            prepend apiSchemas = ["PhysicsCollisionAPI", "MjcCollisionAPI", "PhysicsMeshCollisionAPI", "MaterialBindingAPI"]
                        )
                        {
                            rel material:binding:physics = </tn__xarm7scene_lA/Physics/PhysicsMaterial>
                            uniform token physics:approximation = "convexHull"
                        }

                        def PhysicsRevoluteJoint "joint3" (
                            prepend apiSchemas = ["MjcJointAPI"]
                        )
                        {
                            uniform double mjc:armature = 0.1
                            uniform double mjc:damping = 5
                            uniform double mjc:frictionloss = 1
                            uniform token physics:axis = "Z"
                            rel physics:body0 = </tn__xarm7scene_lA/Geometry/link_base/link1/link2>
                            rel physics:body1 = </tn__xarm7scene_lA/Geometry/link_base/link1/link2/link3>
                            point3f physics:localPos0 = (0, -0.293, 3.3087225e-24)
                            point3f physics:localPos1 = (0, 0, 0)
                            quatf physics:localRot0 = (-0.70710677, -0.70710677, 0, 0)
                            quatf physics:localRot1 = (1, 0, 0, 0)
                            float physics:lowerLimit = -360.00027
                            float physics:upperLimit = 360.00027
                        }

                        def "link4" (
                            prepend apiSchemas = ["PhysicsRigidBodyAPI", "PhysicsMassAPI"]
                        )
                        {
                            point3f physics:centerOfMass = (0.07047, -0.11575, 0.012)
                            float3 physics:diagonalInertia = (0.00657137, 0.00647948, 0.00186763)
                            float physics:mass = 1.7269
                            quatf physics:principalAxes = (0.422108, 0.852026, -0.126025, 0.282832)

                            over "link4" (
                                prepend apiSchemas = ["PhysicsCollisionAPI", "MjcCollisionAPI", "PhysicsMeshCollisionAPI", "MaterialBindingAPI"]
                            )
                            {
                                rel material:binding:physics = </tn__xarm7scene_lA/Physics/PhysicsMaterial>
                                uniform token physics:approximation = "convexHull"
                            }

                            def PhysicsRevoluteJoint "joint4" (
                                prepend apiSchemas = ["MjcJointAPI"]
                            )
                            {
                                uniform double mjc:armature = 0.1
                                uniform double mjc:damping = 5
                                uniform double mjc:frictionloss = 1
                                uniform token physics:axis = "Z"
                                rel physics:body0 = </tn__xarm7scene_lA/Geometry/link_base/link1/link2/link3>
                                rel physics:body1 = </tn__xarm7scene_lA/Geometry/link_base/link1/link2/link3/link4>
                                point3f physics:localPos0 = (0.0525, 0, 0)
                                point3f physics:localPos1 = (0, 0, 0)
                                quatf physics:localRot0 = (0.70710677, 0.70710677, 0, 0)
                                quatf physics:localRot1 = (1, 0, 0, 0)
                                float physics:lowerLimit = -10.999643
                                float physics:upperLimit = 225.00052
                            }

                            def "link5" (
                                prepend apiSchemas = ["PhysicsRigidBodyAPI", "PhysicsMassAPI"]
                            )
                            {
                                point3f physics:centerOfMass = (-0.00032, 0.01604, -0.026)
                                float3 physics:diagonalInertia = (0.00534729, 0.00499076, 0.0013489)
                                float physics:mass = 1.3203
                                quatf physics:principalAxes = (0.999311, -0.0304457, 0.000577067, 0.0212082)

                                over "link5" (
                                    prepend apiSchemas = ["PhysicsCollisionAPI", "MjcCollisionAPI", "PhysicsMeshCollisionAPI", "MaterialBindingAPI"]
                                )
                                {
                                    rel material:binding:physics = </tn__xarm7scene_lA/Physics/PhysicsMaterial>
                                    uniform token physics:approximation = "convexHull"
                                }

                                def PhysicsRevoluteJoint "joint5" (
                                    prepend apiSchemas = ["MjcJointAPI"]
                                )
                                {
                                    uniform double mjc:armature = 0.1
                                    uniform double mjc:damping = 5
                                    uniform double mjc:frictionloss = 1
                                    uniform token physics:axis = "Z"
                                    rel physics:body0 = </tn__xarm7scene_lA/Geometry/link_base/link1/link2/link3/link4>
                                    rel physics:body1 = </tn__xarm7scene_lA/Geometry/link_base/link1/link2/link3/link4/link5>
                                    point3f physics:localPos0 = (0.0775, -0.3425, -6.617445e-24)
                                    point3f physics:localPos1 = (0, 0, 0)
                                    quatf physics:localRot0 = (0.70710677, 0.70710677, 0, 0)
                                    quatf physics:localRot1 = (1, 0, 0, 0)
                                    float physics:lowerLimit = -360.00027
                                    float physics:upperLimit = 360.00027
                                }

                                def "link6" (
                                    prepend apiSchemas = ["PhysicsRigidBodyAPI", "PhysicsMassAPI"]
                                )
                                {
                                    point3f physics:centerOfMass = (0.06469, 0.03278, 0.02141)
                                    float3 physics:diagonalInertia = (0.00245421, 0.00221646, 0.00107273)
                                    float physics:mass = 1.325
                                    quatf physics:principalAxes = (-0.217672, 0.772419, 0.16258, 0.574069)

                                    over "link6" (
                                        prepend apiSchemas = ["PhysicsCollisionAPI", "MjcCollisionAPI", "PhysicsMeshCollisionAPI", "MaterialBindingAPI"]
                                    )
                                    {
                                        rel material:binding:physics = </tn__xarm7scene_lA/Physics/PhysicsMaterial>
                                        uniform token physics:approximation = "convexHull"
                                    }

                                    def PhysicsRevoluteJoint "joint6" (
                                        prepend apiSchemas = ["MjcJointAPI"]
                                    )
                                    {
                                        uniform double mjc:armature = 0.1
                                        uniform double mjc:damping = 2
                                        uniform double mjc:frictionloss = 1
                                        uniform token physics:axis = "Z"
                                        rel physics:body0 = </tn__xarm7scene_lA/Geometry/link_base/link1/link2/link3/link4/link5>
                                        rel physics:body1 = </tn__xarm7scene_lA/Geometry/link_base/link1/link2/link3/link4/link5/link6>
                                        point3f physics:localPos0 = (-2.7755576e-17, 0, 0)
                                        point3f physics:localPos1 = (0, 0, 0)
                                        quatf physics:localRot0 = (-0.70710677, -0.70710677, 0, -0)
                                        quatf physics:localRot1 = (1, 0, 0, 0)
                                        float physics:lowerLimit = -97.00004
                                        float physics:upperLimit = 179.99985
                                    }

                                    def "link7" (
                                        prepend apiSchemas = ["PhysicsRigidBodyAPI", "PhysicsMassAPI"]
                                    )
                                    {
                                        point3f physics:centerOfMass = (0, -0.00677, -0.01098)
                                        float3 physics:diagonalInertia = (0.000132176, 0.000093, 0.0000585236)
                                        float physics:mass = 0.17
                                        quatf physics:principalAxes = (0.487612, 0.512088, -0.512088, 0.487612)

                                        over "end_tool" (
                                            prepend apiSchemas = ["PhysicsCollisionAPI", "MjcCollisionAPI", "PhysicsMeshCollisionAPI", "MaterialBindingAPI"]
                                        )
                                        {
                                            rel material:binding:physics = </tn__xarm7scene_lA/Physics/PhysicsMaterial>
                                            uniform token physics:approximation = "convexHull"
                                        }

                                        def PhysicsRevoluteJoint "joint7" (
                                            prepend apiSchemas = ["MjcJointAPI"]
                                        )
                                        {
                                            uniform double mjc:armature = 0.1
                                            uniform double mjc:damping = 2
                                            uniform double mjc:frictionloss = 1
                                            uniform token physics:axis = "Z"
                                            rel physics:body0 = </tn__xarm7scene_lA/Geometry/link_base/link1/link2/link3/link4/link5/link6>
                                            rel physics:body1 = </tn__xarm7scene_lA/Geometry/link_base/link1/link2/link3/link4/link5/link6/link7>
                                            point3f physics:localPos0 = (0.076, 0.097, 0)
                                            point3f physics:localPos1 = (0, 0, 0)
                                            quatf physics:localRot0 = (-0.70710677, 0.70710677, 0, 0)
                                            quatf physics:localRot1 = (1, 0, 0, 0)
                                            float physics:lowerLimit = -360.00027
                                            float physics:upperLimit = 360.00027
                                        }

                                        def "xarm_gripper_base_link" (
                                            prepend apiSchemas = ["PhysicsRigidBodyAPI", "PhysicsMassAPI"]
                                        )
                                        {
                                            point3f physics:centerOfMass = (-0.00065489, -0.0018497, 0.048028)
                                            float3 physics:diagonalInertia = (0.000471093, 0.000332307, 0.000254799)
                                            float physics:mass = 0.54156
                                            quatf physics:principalAxes = (0.997403, -0.0717512, -0.0061836, 0.000477479)

                                            over "link_tcp" (
                                                prepend apiSchemas = ["MjcSiteAPI"]
                                            )
                                            {
                                                uniform int mjc:group = 4
                                            }

                                            def PhysicsFixedJoint "PhysicsFixedJoint"
                                            {
                                                rel physics:body0 = </tn__xarm7scene_lA/Geometry/link_base/link1/link2/link3/link4/link5/link6/link7>
                                                rel physics:body1 = </tn__xarm7scene_lA/Geometry/link_base/link1/link2/link3/link4/link5/link6/link7/xarm_gripper_base_link>
                                                point3f physics:localPos0 = (0, 0, 0)
                                                point3f physics:localPos1 = (0, 0, 0)
                                                quatf physics:localRot0 = (-6.123234e-17, -6.1232336e-17, 6.1232356e-17, -1)
                                                quatf physics:localRot1 = (1, 0, 0, 0)
                                            }

                                            def "left_outer_knuckle" (
                                                prepend apiSchemas = ["PhysicsRigidBodyAPI", "PhysicsMassAPI"]
                                            )
                                            {
                                                point3f physics:centerOfMass = (0, 0.021559, 0.015181)
                                                float3 physics:diagonalInertia = (0.000019111, 0.0000179089, 0.00000190167)
                                                float physics:mass = 0.033618
                                                quatf physics:principalAxes = (0.47789, 0.87842, 0, 0)

                                                over "left_outer_knuckle" (
                                                    prepend apiSchemas = ["PhysicsCollisionAPI", "MjcCollisionAPI", "PhysicsMeshCollisionAPI", "MaterialBindingAPI"]
                                                )
                                                {
                                                    rel material:binding:physics = </tn__xarm7scene_lA/Physics/PhysicsMaterial>
                                                    uniform token physics:approximation = "convexHull"
                                                }

                                                def PhysicsRevoluteJoint "left_driver_joint" (
                                                    prepend apiSchemas = ["MjcJointAPI"]
                                                )
                                                {
                                                    uniform double mjc:armature = 0.005
                                                    uniform double mjc:damping = 0.1
                                                    uniform double mjc:frictionloss = 1
                                                    uniform double[] mjc:solreflimit = [0.005, 1]
                                                    uniform token physics:axis = "X"
                                                    rel physics:body0 = </tn__xarm7scene_lA/Geometry/link_base/link1/link2/link3/link4/link5/link6/link7/xarm_gripper_base_link>
                                                    rel physics:body1 = </tn__xarm7scene_lA/Geometry/link_base/link1/link2/link3/link4/link5/link6/link7/xarm_gripper_base_link/left_outer_knuckle>
                                                    point3f physics:localPos0 = (0, 0.035, 0.059098)
                                                    point3f physics:localPos1 = (0, 0, 0)
                                                    quatf physics:localRot0 = (1, 0, 0, 0)
                                                    quatf physics:localRot1 = (1, 0, 0, 0)
                                                    float physics:lowerLimit = 0
                                                    float physics:upperLimit = 48.701412
                                                }

                                                def "left_finger" (
                                                    prepend apiSchemas = ["PhysicsRigidBodyAPI", "PhysicsMassAPI"]
                                                )
                                                {
                                                    point3f physics:centerOfMass = (0, -0.016413, 0.029258)
                                                    float3 physics:diagonalInertia = (0.0000188037, 0.000017493, 0.00000356792)
                                                    float physics:mass = 0.048304
                                                    quatf physics:principalAxes = (0.697634, 0.115353, -0.115353, 0.697634)

                                                    over "left_finger_pad_1" (
                                                        prepend apiSchemas = ["PhysicsCollisionAPI", "MjcCollisionAPI", "PhysicsMassAPI", "MaterialBindingAPI"]
                                                    )
                                                    {
                                                        rel material:binding:physics = </tn__xarm7scene_lA/Physics/PhysicsMaterial_1>
                                                        uniform int mjc:group = 3
                                                        uniform int mjc:priority = 1
                                                        uniform double[] mjc:solimp = [0.95, 0.99, 0.001, 0.5, 2]
                                                        uniform double[] mjc:solref = [0.004, 1]
                                                        float physics:mass = 0
                                                    }

                                                    over "left_finger_pad_2" (
                                                        prepend apiSchemas = ["PhysicsCollisionAPI", "MjcCollisionAPI", "PhysicsMassAPI", "MaterialBindingAPI"]
                                                    )
                                                    {
                                                        rel material:binding:physics = </tn__xarm7scene_lA/Physics/PhysicsMaterial_2>
                                                        uniform int mjc:group = 3
                                                        uniform int mjc:priority = 1
                                                        uniform double[] mjc:solimp = [0.95, 0.99, 0.001, 0.5, 2]
                                                        uniform double[] mjc:solref = [0.004, 1]
                                                        float physics:mass = 0
                                                    }

                                                    def PhysicsRevoluteJoint "left_finger_joint" (
                                                        prepend apiSchemas = ["MjcJointAPI"]
                                                    )
                                                    {
                                                        uniform double mjc:armature = 0.1
                                                        uniform double mjc:frictionloss = 1
                                                        uniform double[] mjc:solreflimit = [0.005, 1]
                                                        uniform token physics:axis = "X"
                                                        rel physics:body0 = </tn__xarm7scene_lA/Geometry/link_base/link1/link2/link3/link4/link5/link6/link7/xarm_gripper_base_link/left_outer_knuckle>
                                                        rel physics:body1 = </tn__xarm7scene_lA/Geometry/link_base/link1/link2/link3/link4/link5/link6/link7/xarm_gripper_base_link/left_outer_knuckle/left_finger>
                                                        point3f physics:localPos0 = (0, 0.035465, 0.042039)
                                                        point3f physics:localPos1 = (0, 0, 0)
                                                        quatf physics:localRot0 = (0, 0, -1, 0)
                                                        quatf physics:localRot1 = (0, 0, -1, 0)
                                                        float physics:lowerLimit = 0
                                                        float physics:upperLimit = 48.701412
                                                    }
                                                }
                                            }

                                            def "left_inner_knuckle" (
                                                prepend apiSchemas = ["PhysicsRigidBodyAPI", "PhysicsMassAPI"]
                                            )
                                            {
                                                point3f physics:centerOfMass = (0.00000186601, 0.0220468, 0.0261335)
                                                float3 physics:diagonalInertia = (0.00000834216, 0.0000060949, 0.00000275601)
                                                float physics:mass = 0.0230126
                                                quatf physics:principalAxes = (0.664139, -0.242732, 0.242713, 0.664146)

                                                over "left_inner_knuckle" (
                                                    prepend apiSchemas = ["PhysicsCollisionAPI", "MjcCollisionAPI", "PhysicsMeshCollisionAPI", "MaterialBindingAPI"]
                                                )
                                                {
                                                    rel material:binding:physics = </tn__xarm7scene_lA/Physics/PhysicsMaterial>
                                                    uniform token physics:approximation = "convexHull"
                                                }

                                                def PhysicsRevoluteJoint "left_inner_knuckle_joint" (
                                                    prepend apiSchemas = ["MjcJointAPI"]
                                                )
                                                {
                                                    uniform double mjc:armature = 0.1
                                                    uniform double mjc:damping = 0.00125
                                                    uniform double mjc:frictionloss = 1
                                                    uniform double mjc:springref = 2.62
                                                    uniform double mjc:stiffness = 0.05
                                                    uniform token physics:axis = "X"
                                                    rel physics:body0 = </tn__xarm7scene_lA/Geometry/link_base/link1/link2/link3/link4/link5/link6/link7/xarm_gripper_base_link>
                                                    rel physics:body1 = </tn__xarm7scene_lA/Geometry/link_base/link1/link2/link3/link4/link5/link6/link7/xarm_gripper_base_link/left_inner_knuckle>
                                                    point3f physics:localPos0 = (0, 0.02, 0.074098)
                                                    point3f physics:localPos1 = (0, 0, 0)
                                                    quatf physics:localRot0 = (1, 0, 0, 0)
                                                    quatf physics:localRot1 = (1, 0, 0, 0)
                                                    float physics:lowerLimit = 0
                                                    float physics:upperLimit = 48.701412
                                                }
                                            }

                                            def "right_outer_knuckle" (
                                                prepend apiSchemas = ["PhysicsRigidBodyAPI", "PhysicsMassAPI"]
                                            )
                                            {
                                                point3f physics:centerOfMass = (0, -0.021559, 0.015181)
                                                float3 physics:diagonalInertia = (0.000019111, 0.0000179089, 0.00000190167)
                                                float physics:mass = 0.033618
                                                quatf physics:principalAxes = (0.87842, 0.47789, 0, 0)

                                                over "right_outer_knuckle" (
                                                    prepend apiSchemas = ["PhysicsCollisionAPI", "MjcCollisionAPI", "PhysicsMeshCollisionAPI", "MaterialBindingAPI"]
                                                )
                                                {
                                                    rel material:binding:physics = </tn__xarm7scene_lA/Physics/PhysicsMaterial>
                                                    uniform token physics:approximation = "convexHull"
                                                }

                                                def PhysicsRevoluteJoint "right_driver_joint" (
                                                    prepend apiSchemas = ["MjcJointAPI"]
                                                )
                                                {
                                                    uniform double mjc:armature = 0.005
                                                    uniform double mjc:damping = 0.1
                                                    uniform double mjc:frictionloss = 1
                                                    uniform double[] mjc:solreflimit = [0.005, 1]
                                                    uniform token physics:axis = "X"
                                                    rel physics:body0 = </tn__xarm7scene_lA/Geometry/link_base/link1/link2/link3/link4/link5/link6/link7/xarm_gripper_base_link>
                                                    rel physics:body1 = </tn__xarm7scene_lA/Geometry/link_base/link1/link2/link3/link4/link5/link6/link7/xarm_gripper_base_link/right_outer_knuckle>
                                                    point3f physics:localPos0 = (0, -0.035, 0.059098)
                                                    point3f physics:localPos1 = (0, 0, 0)
                                                    quatf physics:localRot0 = (0, 0, -1, 0)
                                                    quatf physics:localRot1 = (0, 0, -1, 0)
                                                    float physics:lowerLimit = 0
                                                    float physics:upperLimit = 48.701412
                                                }

                                                def "right_finger" (
                                                    prepend apiSchemas = ["PhysicsRigidBodyAPI", "PhysicsMassAPI"]
                                                )
                                                {
                                                    point3f physics:centerOfMass = (0, 0.016413, 0.029258)
                                                    float3 physics:diagonalInertia = (0.0000188038, 0.000017493, 0.00000356779)
                                                    float physics:mass = 0.048304
                                                    quatf physics:principalAxes = (0.697634, -0.115356, 0.115356, 0.697634)

                                                    over "right_finger_pad_1" (
                                                        prepend apiSchemas = ["PhysicsCollisionAPI", "MjcCollisionAPI", "PhysicsMassAPI", "MaterialBindingAPI"]
                                                    )
                                                    {
                                                        rel material:binding:physics = </tn__xarm7scene_lA/Physics/PhysicsMaterial_1>
                                                        uniform int mjc:group = 3
                                                        uniform int mjc:priority = 1
                                                        uniform double[] mjc:solimp = [0.95, 0.99, 0.001, 0.5, 2]
                                                        uniform double[] mjc:solref = [0.004, 1]
                                                        float physics:mass = 0
                                                    }

                                                    over "right_finger_pad_2" (
                                                        prepend apiSchemas = ["PhysicsCollisionAPI", "MjcCollisionAPI", "PhysicsMassAPI", "MaterialBindingAPI"]
                                                    )
                                                    {
                                                        rel material:binding:physics = </tn__xarm7scene_lA/Physics/PhysicsMaterial_2>
                                                        uniform int mjc:group = 3
                                                        uniform int mjc:priority = 1
                                                        uniform double[] mjc:solimp = [0.95, 0.99, 0.001, 0.5, 2]
                                                        uniform double[] mjc:solref = [0.004, 1]
                                                        float physics:mass = 0
                                                    }

                                                    def PhysicsRevoluteJoint "right_finger_joint" (
                                                        prepend apiSchemas = ["MjcJointAPI"]
                                                    )
                                                    {
                                                        uniform double mjc:armature = 0.1
                                                        uniform double mjc:frictionloss = 1
                                                        uniform double[] mjc:solreflimit = [0.005, 1]
                                                        uniform token physics:axis = "X"
                                                        rel physics:body0 = </tn__xarm7scene_lA/Geometry/link_base/link1/link2/link3/link4/link5/link6/link7/xarm_gripper_base_link/right_outer_knuckle>
                                                        rel physics:body1 = </tn__xarm7scene_lA/Geometry/link_base/link1/link2/link3/link4/link5/link6/link7/xarm_gripper_base_link/right_outer_knuckle/right_finger>
                                                        point3f physics:localPos0 = (0, -0.035465, 0.042039)
                                                        point3f physics:localPos1 = (0, 0, 0)
                                                        quatf physics:localRot0 = (1, 0, 0, 0)
                                                        quatf physics:localRot1 = (1, 0, 0, 0)
                                                        float physics:lowerLimit = 0
                                                        float physics:upperLimit = 48.701412
                                                    }
                                                }
                                            }

                                            def "right_inner_knuckle" (
                                                prepend apiSchemas = ["PhysicsRigidBodyAPI", "PhysicsMassAPI"]
                                            )
                                            {
                                                point3f physics:centerOfMass = (0.000001866, -0.022047, 0.026133)
                                                float3 physics:diagonalInertia = (0.00000834209, 0.0000060949, 0.00000275601)
                                                float physics:mass = 0.023013
                                                quatf physics:principalAxes = (0.66415, 0.242702, -0.242721, 0.664144)

                                                over "right_inner_knuckle" (
                                                    prepend apiSchemas = ["PhysicsCollisionAPI", "MjcCollisionAPI", "PhysicsMeshCollisionAPI", "MaterialBindingAPI"]
                                                )
                                                {
                                                    rel material:binding:physics = </tn__xarm7scene_lA/Physics/PhysicsMaterial>
                                                    uniform token physics:approximation = "convexHull"
                                                }

                                                def PhysicsRevoluteJoint "right_inner_knuckle_joint" (
                                                    prepend apiSchemas = ["MjcJointAPI"]
                                                )
                                                {
                                                    uniform double mjc:armature = 0.1
                                                    uniform double mjc:damping = 0.00125
                                                    uniform double mjc:frictionloss = 1
                                                    uniform double mjc:springref = 2.62
                                                    uniform double mjc:stiffness = 0.05
                                                    uniform token physics:axis = "X"
                                                    rel physics:body0 = </tn__xarm7scene_lA/Geometry/link_base/link1/link2/link3/link4/link5/link6/link7/xarm_gripper_base_link>
                                                    rel physics:body1 = </tn__xarm7scene_lA/Geometry/link_base/link1/link2/link3/link4/link5/link6/link7/xarm_gripper_base_link/right_inner_knuckle>
                                                    point3f physics:localPos0 = (0, -0.02, 0.074098)
                                                    point3f physics:localPos1 = (0, 0, 0)
                                                    quatf physics:localRot0 = (0, 0, -1, 0)
                                                    quatf physics:localRot1 = (0, 0, -1, 0)
                                                    float physics:lowerLimit = 0
                                                    float physics:upperLimit = 48.701412
                                                }
                                            }
                                        }
                                    }
                                }
                            }
                        }
                    }
                }
            }
        }
    }
}

def PhysicsScene "PhysicsScene" (
    prepend apiSchemas = ["MjcSceneAPI"]
)
{
    uniform token mjc:compiler:angle = "radian"
    uniform token mjc:option:integrator = "implicitfast"
    vector3f physics:gravityDirection = (0, 0, -1)
    float physics:gravityMagnitude = 9.81
}

