<?xml version='1.0' encoding='utf-8'?>
<mujoco model="mycobot_280_m5">
  <compiler angle="radian" meshdir="meshes_mujoco" />
  <option integrator="RK4" gravity="0 0 -9.81" />
  <default>
    <default class="visual">
      <geom type="mesh" rgba="0.85 0.85 0.85 1" contype="0" conaffinity="0" group="2" />
    </default>
    <default class="collision">
      <geom type="capsule" group="3" contype="1" conaffinity="1" />
    </default>
  </default>
  <asset>
    <mesh name="joint2_vis" file="../meshes_mujoco/joint2.obj" />
    <mesh name="joint3_vis" file="../meshes_mujoco/joint3.obj" />
    <mesh name="joint4_vis" file="../meshes_mujoco/joint4.obj" />
    <mesh name="joint5_vis" file="../meshes_mujoco/joint5.obj" />
    <mesh name="joint6_vis" file="../meshes_mujoco/joint6.obj" />
    <mesh name="joint7_vis" file="../meshes_mujoco/joint7.obj" />
    <mesh name="mycobot_base" file="../meshes_mujoco/mycobot_base.obj" />
    <mesh name="joint_1_mycobot" file="../meshes_mujoco/joint1.obj" />
    <mesh name="camera" file="../meshes_mujoco/camera.obj" />
    <mesh name="gripper_base" file="../meshes_mujoco/gripper_base.obj" />
    <mesh name="gripper_left1" file="../meshes_mujoco/gripper_left1.obj" />
    <mesh name="gripper_left2" file="../meshes_mujoco/gripper_left2.obj" />
    <mesh name="gripper_left3" file="../meshes_mujoco/gripper_left3.obj" />
    <mesh name="gripper_right1" file="../meshes_mujoco/gripper_right1.obj" />
    <mesh name="gripper_right2" file="../meshes_mujoco/gripper_right2.obj" />
    <mesh name="gripper_right3" file="../meshes_mujoco/gripper_right3.obj" />
  </asset>
  <worldbody>
    <body name="mycobot_base" pos="0 0 0" euler="1.5708 -1.5708 0 ">
      <geom mesh="mycobot_base" class="visual" />
      <body name="joint0" pos="0 0.032 0.0" euler="-1.5708 0 0">
        <geom mesh="joint_1_mycobot" pos="0 0 0" quat="0.000796327 0 0 1" class="visual" />
        <body name="joint1" pos="0.0 0.002 0.132" euler="0 0 -1.5708">
          <joint name="joint1" damping="1.2" armature="0.05" actuatorfrcrange="-20 20" />
          <geom mesh="joint2_vis" pos="0 0 -0.06096" quat="0.707105 0 0 -0.707108" class="visual" />
          <body name="joint2" pos="0 0 -0.001" quat="0.499998 0.500002 0.5 -0.5">
            <joint name="joint2" damping="1.2" armature="0.05" actuatorfrcrange="-20 20" />
            <geom mesh="joint3_vis" pos="0 0 0.03256" quat="0.707105 0 -0.707108 0" class="visual" />
            <body name="joint3" pos="-0.1104 0 0">
              <joint name="joint3" damping="1.2" armature="0.05" actuatorfrcrange="-20 20" />
              <geom mesh="joint4_vis" pos="0 0 0.03056" quat="0.707105 0 -0.707108 0" class="visual" />
              <body name="joint4" pos="-0.096 0 0.06462" quat="0.707105 0 0 -0.707108">
                <joint name="joint4" damping="1.2" armature="0.05" actuatorfrcrange="-20 20" />
                <geom mesh="joint5_vis" pos="0 0 -0.03356" quat="0.707105 -0.707108 0 0" class="visual" />
                <body name="joint5" pos="0 -0.07318 0" quat="0.499998 0.5 -0.5 0.500002">
                  <joint name="joint5" damping="1.2" armature="0.05" actuatorfrcrange="-20 20" />
                  <geom mesh="joint6_vis" pos="0 0 -0.038" class="visual" />
                  <body name="joint6_flange" pos="0 0.0456 0" euler="-1.5708 0.0 -1.5708">
                    <joint name="joint6" damping="1.2" armature="0.05" actuatorfrcrange="-20 20" />
                    <geom mesh="joint7_vis" pos="0 0 -0.012" class="visual" />
                    <body name="camera" pos="0.018 -0.018 0.0025" euler="0 3.141 0.7854">
                      <geom mesh="camera" pos="0 0 0" size="0.02" class="visual" />
                      <body name="gripper_base" pos="-0.04 0.00 -0.03725" euler="0 1.5708 2.3562">
                        <geom pos="-0.0087164 -0.00825415 0.0509987" quat="-0.273017 -0.267658 -0.654494 -0.652272" type="mesh" mesh="gripper_base" rgba="0.85 0.85 0.85 1" />
                        <body name="gripper_left3" pos="0.00826547 -0.00825205 0.0490971" quat="-0.273017 -0.267658 -0.654494 -0.652272">
                          <joint name="gripper_controller" pos="-0.001 -0.0045 -0.0095" axis="0 -1 0" actuatorfrcrange="-20 20" damping="1" armature="0.005" />
                          <geom pos="0.012 0.0025 -0.012" quat="1 0 0 0" type="mesh" mesh="gripper_left3" rgba="0.85 0.85 0.85 1" />
                          <body name="gripper_left1" pos="-0.027 0.016 0">
                            <joint name="gripper_left3_to_gripper_left1" pos="-0.0014 -0.02 -0.0248" axis="0 1 0" range="-0.5 0.5" />
                            <geom pos="0.039 -0.0133 -0.012" type="mesh" mesh="gripper_left1" rgba="0.85 0.85 0.85 1" />
                            <geom pos="0.039 -0.0133 -0.012" type="mesh" mesh="gripper_left1" class="collision" rgba="0.85 0.85 0.85 1" />
                          </body>
                        </body>
                        <body name="gripper_left2" pos="0.00318726 -0.00318167 0.070539" quat="-0.273017 -0.267658 -0.654494 -0.652272">
                          <joint name="gripper_base_to_gripper_left2" pos="-0.001 -0.025 -0.03135" axis="0 1 0" range="-0.8 0.5" />
                          <geom pos="0.005 -0.0195 -0.012" quat="1 0 0 0" type="mesh" mesh="gripper_left2" rgba="0.85 0.85 0.85 1" />
                        </body>
                        <body name="gripper_right3" pos="-0.00871793 0.00870452 0.0489002" quat="-0.273017 -0.267658 -0.654494 -0.652272">
                          <joint name="gripper_base_to_gripper_right3" pos="0.00026 -0.0065 -0.0095" axis="0 1 0" range="-0.15 0.7" />
                          <geom pos="-0.012 0.0025 -0.012" quat="1 0 0 0" type="mesh" mesh="gripper_right3" rgba="0.85 0.85 0.85 1" />
                          <body name="gripper_right1" pos="0.027 0.016 0">
                            <joint name="gripper_right3_to_gripper_right1" pos="-0.0002 -0.02 -0.025" axis="0 1 0" range="-0.5 0.5" />
                            <geom pos="-0.039 -0.0133 -0.012" type="mesh" mesh="gripper_right1" rgba="0.85 0.85 0.85 1" />
                            <geom pos="-0.039 -0.0133 -0.012" type="mesh" mesh="gripper_right1" class="collision" rgba="0.85 0.85 0.85 1" />
                          </body>
                        </body>
                        <body name="gripper_right2" pos="-0.00388916 0.00388357 0.0704569" quat="-0.273017 -0.267658 -0.654494 -0.652272">
                          <joint name="gripper_base_to_gripper_right2" pos="-0.00 -0.025 -0.03135" axis="0 1 0" range="-0.5 0.8" />
                          <geom pos="-0.005 -0.0195 -0.012" quat="1 0 0 0" type="mesh" mesh="gripper_right2" rgba="0.85 0.85 0.85 1" />
                        </body>
                      </body>
                    </body>
                  </body>
                </body>
              </body>
            </body>
          </body>
        </body>
      </body>
    </body>
  </worldbody>
  <actuator>
    <position name="joint1_motor" joint="joint1" kp="60" dampratio="1" ctrllimited="true" ctrlrange="-2.79253 2.79253" />
    <position name="joint2_motor" joint="joint2" kp="60" dampratio="1" ctrllimited="true" ctrlrange="-2.79253 2.79253" />
    <position name="joint3_motor" joint="joint3" kp="60" dampratio="1" ctrllimited="true" ctrlrange="-2.79253 2.79253" />
    <position name="joint4_motor" joint="joint4" kp="60" dampratio="1" ctrllimited="true" ctrlrange="-2.79253 2.79253" />
    <position name="joint5_motor" joint="joint5" kp="60" dampratio="1" ctrllimited="true" ctrlrange="-2.79253 2.79253" />
    <position name="joint6_motor" joint="joint6" kp="60" dampratio="1" ctrllimited="true" ctrlrange="-2.96706 2.96706" />
    <position name="gripper_motor" tendon="gripper_controller_joint" kp="60" ctrllimited="true" ctrlrange="-0.74 0.15" />
  </actuator>
  <equality>
    <connect body1="gripper_left1" body2="gripper_left2" anchor="0.006 0 -0.046" solref="0.005 1" />
    <connect body1="gripper_right1" body2="gripper_right2" anchor="-0.007 0 -0.047" solref="0.005 1" />
    <joint joint1="gripper_controller" joint2="gripper_base_to_gripper_right3" polycoef="0 1 0 0 0" solref="0.005 1" />
  </equality>
  <tendon>
    <fixed name="gripper_controller_joint">
      <joint joint="gripper_controller" coef="0.4" />
      <joint joint="gripper_base_to_gripper_right3" coef="0.4" />
    </fixed>
  </tendon>
  <keyframe>
    <key name="home" qpos="0 0 0 0 0 0 0 0 0 0 0 0 0 0 0 0 0 0 0 0 0 0 0 0 0 0" />
  </keyframe>
</mujoco>