<?xml version="1.0"?>
<robot  xmlns:xacro="http://www.ros.org/wiki/xacro" name="firefighter" >
	
<xacro:property name="width" value=".2" />


  <link name="mycobot_base">
    <visual>
      <geometry>
        <mesh filename="package://robot_description/urdf/mycobot_280_m5/mycobot_base.dae"/>
      </geometry>
      <origin xyz = "0.0 0 -0.03" rpy = "0 0 1.5708"/>
    </visual>
    <collision>
      <geometry>
        <mesh filename="package://robot_description/urdf/mycobot_280_m5/mycobot_base.dae"/>
      </geometry>
      <origin xyz = "0.0 0 -0.03" rpy = "0 0 1.5708"/>
    </collision>
  </link>

  <link name="link1">
    <visual>
      <geometry>
	     <!--- 0.0 0 -0.04  1.5708 3.14159-->
       <mesh filename="package://robot_description/urdf/mycobot_280_m5/joint1.dae"/>
      </geometry>
      <origin xyz = "0.0 0 0 " rpy = " 0 0 -1.5708"/>
    </visual>
    <collision>
      <geometry>
	     <!--- 0.0 0 -0.04  1.5708 3.14159-->
       <mesh filename="package://robot_description/urdf/mycobot_280_m5/joint1.dae"/>
        </geometry>
        <origin xyz = "0.0 0 0 " rpy = " 0 0 -1.5708"/>
    </collision>
  </link>

  <link name="link2">
    <visual>
      <geometry>
       <mesh filename="package://robot_description/urdf/mycobot_280_m5/joint2.dae"/>
      </geometry>
      <origin xyz = "0.0 0 -0.06096 " rpy = " 0 0 -1.5708"/>
    </visual>
    <collision>
     <geometry>
       <mesh filename="package://robot_description/urdf/mycobot_280_m5/joint2.dae"/>
      </geometry>
      <origin xyz = "0.0 0 -0.06096 " rpy = " 0 0 -1.5708"/>
    </collision>
  </link>


  <link name="link3">
    <visual>
      <geometry>
       <mesh filename="package://robot_description/urdf/mycobot_280_m5/joint3.dae"/>
      </geometry>
    <origin xyz = "0.0 0 0.03256 " rpy = " 0 -1.5708 0"/>
    </visual>
    <collision>
      <geometry>
       <mesh filename="package://robot_description/urdf/mycobot_280_m5/joint3.dae"/>
      </geometry>
      <origin xyz = "0.0 0 0.03256 " rpy = " 0 -1.5708 0"/>
    </collision>
  </link>


  <link name="link4">
    <visual>
      <geometry>
       <!--- 0.0 0 -0.04 -->
       <mesh filename="package://robot_description/urdf/mycobot_280_m5/joint4.dae"/>
      </geometry>
      <origin xyz = "0.0 0 0.03056 " rpy = " 0 -1.5708 0"/>
    </visual>
    <collision>
      <geometry>
       <!--- 0.0 0 -0.04 -->
       <mesh filename="package://robot_description/urdf/mycobot_280_m5/joint4.dae"/>
      </geometry>
      <origin xyz = "0.0 0 0.03056 " rpy = " 0 -1.5708 0"/>
    </collision>
  </link>


  <link name="link5">
    <visual>
      <geometry>
       <!--- 0.0 0 -0.04 -->
       <mesh filename="package://robot_description/urdf/mycobot_280_m5/joint5.dae"/>
      </geometry>
    <origin xyz = "0.0 0 -0.03356 " rpy = " -1.5708 0 0"/>
    </visual>
    <collision>
       <geometry>
       <!--- 0.0 0 -0.04 -->
       <mesh filename="package://robot_description/urdf/mycobot_280_m5/joint5.dae"/>
      </geometry>
      <origin xyz = "0.0 0 -0.03356 " rpy = " -1.5708 0 0"/>
    </collision>
  </link>


  <link name="link6">
    <visual>
      <geometry>
       <!--- 0.0 0 -0.04 -->
       <mesh filename="package://robot_description/urdf/mycobot_280_m5/joint6.dae"/>
      </geometry>
    <origin xyz = "0 0.00 -0.038 " rpy = " 0 0 0"/>
    </visual>
    <collision>
      <geometry>
       <!--- 0.0 0 -0.04 -->
       <mesh filename="package://robot_description/urdf/mycobot_280_m5/joint6.dae"/>
      </geometry>
    <origin xyz = "0 0.00 -0.038 " rpy = " 0 0 0"/>
    </collision>
  </link>


  <link name="link7">
    <visual>
      <geometry>
       <!--- 0.0 0 -0.04 -->
       <mesh filename="package://robot_description/urdf/mycobot_280_m5/joint7.dae"/>
      </geometry>
    <origin xyz = "0.0 0 -0.012 " rpy = " 0 0 0"/>
    </visual>
    <collision>
      <geometry>
       <!--- 0.0 0 -0.04 -->
       <mesh filename="package://robot_description/urdf/mycobot_280_m5/joint7.dae"/>
      </geometry>
    <origin xyz = "0.0 0 -0.012 " rpy = " 0 0 0"/>
    </collision>
  </link>

 <!-- Camera -->
  <link name="camera">
    <visual>
      <geometry>
       <mesh filename="package://robot_description/urdf/mycobot_280_m5/camera.dae"/>
      </geometry>
    <origin xyz = "0.024 -0.008 0.0 " rpy = " 0 3.14159 0"/>
    </visual>
    <collision>
      <geometry>
       <mesh filename="package://robot_description/urdf/mycobot_280_m5/camera.dae"/>
      </geometry>
    <origin xyz = "0.024 -0.008 0.0 " rpy = " 0 3.14159 0"/>
    </collision>
  </link>


 <!-- Gripper -->
  <link name="gripper_base">
    <visual>
      <geometry>
       <mesh filename="package://robot_description/urdf/adaptive_gripper/gripper_base.dae"/>
      </geometry>
    <origin xyz = "0.0 0 -0.012 " rpy = " 0 0 0"/>
    </visual>
    <collision>
      <geometry>
       <mesh filename="package://robot_description/urdf/adaptive_gripper/gripper_base.dae"/>
      </geometry>
    <origin xyz = "0.0 0 -0.012 " rpy = " 0 0 0"/>
    </collision>
  </link>

  <link name="gripper_left1">
    <visual>
      <geometry>
       <mesh filename="package://robot_description/urdf/adaptive_gripper/gripper_left1.dae"/>
      </geometry>
    <origin xyz = "0.039 -0.0133 -0.012 " rpy = " 0 0 0"/>
    </visual>
    <collision>
      <geometry>
       <mesh filename="package://robot_description/urdf/adaptive_gripper/gripper_left1.dae"/>
      </geometry>
        <origin xyz = "0.039 -0.0133 -0.012 " rpy = " 0 0 0"/>
    </collision>
  </link>

  <link name="gripper_left2">
    <visual>
      <geometry>
       <mesh filename="package://robot_description/urdf/adaptive_gripper/gripper_left2.dae"/>
      </geometry>
    <origin xyz = "0.005 -0.0195 -0.012 " rpy = " 0 0 0"/>
    </visual>
    <collision>
      <geometry>
       <mesh filename="package://robot_description/urdf/adaptive_gripper/gripper_left2.dae"/>
      </geometry>
        <origin xyz = "0.005 -0.0195 -0.012 " rpy = " 0 0 0"/>
    </collision>
  </link>

  <link name="gripper_left3">
    <visual>
      <geometry>
       <mesh filename="package://robot_description/urdf/adaptive_gripper/gripper_left3.dae"/>
      </geometry>
    <origin xyz = "0.012 0.0025 -0.012 " rpy = " 0 0 0"/>
    </visual>
    <collision>
      <geometry>
       <mesh filename="package://robot_description/urdf/adaptive_gripper/gripper_left3.dae"/>
      </geometry>
    <origin xyz = "0.012 0.0025 -0.012 " rpy = " 0 0 0"/>
    </collision>
  </link>

  <link name="gripper_right1">
    <visual>
      <geometry>
       <mesh filename="package://robot_description/urdf/adaptive_gripper/gripper_right1.dae"/>
      </geometry>
    <origin xyz = "-0.039 -0.0133 -0.012 " rpy = " 0 0 0"/>
    </visual>
    <collision>
      <geometry>
       <mesh filename="package://robot_description/urdf/adaptive_gripper/gripper_right1.dae"/>
      </geometry>
        <origin xyz = "-0.039 -0.0133 -0.012 " rpy = " 0 0 0"/>
    </collision>
  </link>

  <link name="gripper_right2">
    <visual>
      <geometry>
       <mesh filename="package://robot_description/urdf/adaptive_gripper/gripper_right2.dae"/>
      </geometry>
    <origin xyz = "-0.005 -0.0195 -0.012 " rpy = " 0 0 0"/>
    </visual>
    <collision>
      <geometry>
       <mesh filename="package://robot_description/urdf/adaptive_gripper/gripper_right2.dae"/>
      </geometry>
        <origin xyz = "-0.005 -0.0195 -0.012 " rpy = " 0 0 0"/>
    </collision>
  </link>

  <link name="gripper_right3">
    <visual>
      <geometry>
       <mesh filename="package://robot_description/urdf/adaptive_gripper/gripper_right3.dae"/>
      </geometry>
    <origin xyz = "-0.012 0.0025 -0.012 " rpy = " 0 0 0"/>
    </visual>
    <collision>
      <geometry>
       <mesh filename="package://robot_description/urdf/adaptive_gripper/gripper_right3.dae"/>
      </geometry>
    <origin xyz = "-0.012 0.0025 -0.012" rpy = " 0 0 0"/>
    </collision>
  </link>



 <!-- Joints -->
  <joint name="base_joint" type="fixed">
    <axis xyz="0 0 0"/>
    <limit effort = "1000.0" lower = "-3.14" upper = "3.14159" velocity = "0"/>
    <parent link="mycobot_base"/>
    <child link="link1"/>
    <origin xyz= "0 0 0" rpy = "0 0 0"/>  
  </joint>


  <joint name="joint1" type="revolute">
    <axis xyz="0 0 1"/>
    <limit effort = "1000.0" lower = "-2.9322" upper = "2.9322" velocity = "0"/>
    <parent link="link1"/>
    <child link="link2"/>
    <origin xyz= "0 0 0.13156" rpy = "0 0 0"/>  
  </joint>


  <joint name="joint2" type="revolute">
    <axis xyz="0 0 1"/>
    <limit effort = "1000.0" lower = "-2.3562" upper = "2.3562" velocity = "0"/>
    <parent link="link2"/>
    <child link="link3"/>
    <origin xyz= "0 0  0" rpy = "0 1.5708 -1.5708"/>  
  </joint>


  <joint name="joint3" type="revolute">
    <axis xyz=" 0 0 1"/>
    <limit effort = "1000.0" lower = "-2.618" upper = "2.618" velocity = "0"/>
    <parent link="link3"/>
    <child link="link4"/>
    <origin xyz= "  -0.1104 0 0   " rpy = "0 0 0"/>  
  </joint>

  <joint name="joint4" type="revolute">
    <axis xyz=" 0 0 1"/>
    <limit effort = "1000.0" lower = "-2.5307" upper = "2.5307" velocity = "0"/>
    <parent link="link4"/>
    <child link="link5"/>
    <origin xyz= "-0.096 0 0.06462" rpy = "0 0 -1.5708"/>  
  </joint>

  <joint name="joint5" type="revolute">
    <axis xyz="0 0 1"/>
    <limit effort = "1000.0" lower = "-2.8798" upper = "2.8798" velocity = "0"/>
    <parent link="link5"/>
    <child link="link6"/>
    <origin xyz= "0 -0.07318 0" rpy = "1.5708 -1.5708 0"/>  
  </joint>


  <joint name="joint6" type="revolute">
    <axis xyz="0 0 1"/>
    <limit effort = "1000.0" lower = "-3.14159" upper = "3.14159" velocity = "0"/>
    <parent link="link6"/>
    <child link="link7"/>
    <origin xyz= "0 0.0456 0" rpy = "-1.5708 0 0"/>  
  </joint>


  <joint name="joint7_to_camera" type="fixed">
    <parent link="link7"/>
    <child link="camera"/>
    <origin xyz="0 0 0.01" rpy="1.579 0 -2.3562"/>
  </joint>


  <joint name="camera_to_gripper_base" type="fixed">
    <parent link="camera"/>
    <child link="gripper_base"/>
    <origin xyz="0.0 0.041 0.0" rpy="0 -1.57 0"/>
  </joint>


	<!-- Joint that is controlled to open/close the gripper -->
	<joint name="gripper_controller" type="revolute">
    <axis xyz="0 0 1"/>
    <limit effort = "1000.0" lower = "-0.74" upper = "0.15" velocity = "0"/>
    <parent link="gripper_base"/>
    <child link="gripper_left3"/>
    <origin xyz= "-0.012 -0.002 0" rpy = "0 0 0"/> 
  </joint>

  <joint name="gripper_base_to_gripper_left2" type="revolute">
    <axis xyz="0 0 1"/>
    <limit effort = "1000.0" lower = "-0.8" upper = "0.5" velocity = "0"/>
    <parent link="gripper_base"/>
    <child link="gripper_left2"/>
    <origin xyz= "-0.005 0.0195 0" rpy = "0 0 0"/> 
    <mimic joint="gripper_controller" multiplier="1.0" offset="0" />
  </joint>

  <joint name="gripper_left3_to_gripper_left1" type="revolute">
    <axis xyz="0 0 1"/>
    <limit effort = "1000.0" lower = "-0.5" upper = "0.5" velocity = "0"/>
    <parent link="gripper_left3"/>
    <child link="gripper_left1"/>
    <origin xyz= "-0.027 0.016 0" rpy = "0 0 0"/> 
    <mimic joint="gripper_controller" multiplier="-1.0" offset="0" />
  </joint>


  <joint name="gripper_base_to_gripper_right3" type="revolute">
    <axis xyz="0 0 1"/>
    <limit effort = "1000.0" lower = "-0.15" upper = "0.7" velocity = "0"/>
    <parent link="gripper_base"/>
    <child link="gripper_right3"/>
    <origin xyz= "0.012 -0.002 0" rpy = "0 0 0"/> 
    <mimic joint="gripper_controller" multiplier="-1.0" offset="0" />
  </joint>

  <joint name="gripper_base_to_gripper_right2" type="revolute">
    <axis xyz="0 0 1"/>
    <limit effort = "1000.0" lower = "-0.5" upper = "0.8" velocity = "0"/>
    <parent link="gripper_base"/>
    <child link="gripper_right2"/>
    <origin xyz= "0.005 0.0195 0" rpy = "0 0 0"/> 
    <mimic joint="gripper_controller" multiplier="-1.0" offset="0.0" />
  </joint>

  <joint name="gripper_right3_to_gripper_right1" type="revolute">
    <axis xyz="0 0 1"/>
    <limit effort = "1000.0" lower = "-0.5" upper = "0.5" velocity = "0"/>
    <parent link="gripper_right3"/>
    <child link="gripper_right1"/>
    <origin xyz= "0.027 0.016 0" rpy = "0 0 0"/> 
    <mimic joint="gripper_controller" multiplier="1.0" offset="0" />
  </joint>

</robot>

